[2025-04-14T17:01:10.629+0000] {taskinstance.py:1159} INFO - Dependencies all met for dep_context=non-requeueable deps ti=<TaskInstance: etl_reddit_pipeline.reddit_extraction scheduled__2025-04-11T00:00:00+00:00 [queued]>
[2025-04-14T17:01:10.651+0000] {taskinstance.py:1159} INFO - Dependencies all met for dep_context=requeueable deps ti=<TaskInstance: etl_reddit_pipeline.reddit_extraction scheduled__2025-04-11T00:00:00+00:00 [queued]>
[2025-04-14T17:01:10.656+0000] {taskinstance.py:1361} INFO - Starting attempt 1 of 1
[2025-04-14T17:01:10.689+0000] {taskinstance.py:1382} INFO - Executing <Task(PythonOperator): reddit_extraction> on 2025-04-11 00:00:00+00:00
[2025-04-14T17:01:10.706+0000] {standard_task_runner.py:57} INFO - Started process 89 to run task
[2025-04-14T17:01:10.712+0000] {standard_task_runner.py:84} INFO - Running: ['airflow', 'tasks', 'run', 'etl_reddit_pipeline', 'reddit_extraction', 'scheduled__2025-04-11T00:00:00+00:00', '--job-id', '8', '--raw', '--subdir', 'DAGS_FOLDER/reddit_dag.py', '--cfg-path', '/tmp/tmpftv0btgs']
[2025-04-14T17:01:10.718+0000] {standard_task_runner.py:85} INFO - Job 8: Subtask reddit_extraction
[2025-04-14T17:01:10.786+0000] {task_command.py:416} INFO - Running <TaskInstance: etl_reddit_pipeline.reddit_extraction scheduled__2025-04-11T00:00:00+00:00 [running]> on host 5d379c010d2e
[2025-04-14T17:01:10.843+0000] {taskinstance.py:1662} INFO - Exporting env vars: AIRFLOW_CTX_DAG_OWNER='Hari Shankar' AIRFLOW_CTX_DAG_ID='etl_reddit_pipeline' AIRFLOW_CTX_TASK_ID='reddit_extraction' AIRFLOW_CTX_EXECUTION_DATE='2025-04-11T00:00:00+00:00' AIRFLOW_CTX_TRY_NUMBER='1' AIRFLOW_CTX_DAG_RUN_ID='scheduled__2025-04-11T00:00:00+00:00'
[2025-04-14T17:01:10.863+0000] {logging_mixin.py:151} INFO - connected to reddit!
[2025-04-14T17:01:10.870+0000] {sessions.py:161} WARNING - Retrying due to ConnectionError(MaxRetryError("HTTPSConnectionPool(host='www.reddit.com', port=443): Max retries exceeded with url: /api/v1/access_token (Caused by NewConnectionError('<urllib3.connection.HTTPSConnection object at 0xffff6ff09400>: Failed to establish a new connection: [Errno -2] Name or service not known'))")) status: GET https://oauth.reddit.com/r/dataengineering/top
[2025-04-14T17:01:12.815+0000] {python.py:194} INFO - Done. Returned value was: /opt/airflow/data/output/reddit_20250414.csv
[2025-04-14T17:01:12.832+0000] {taskinstance.py:1400} INFO - Marking task as SUCCESS. dag_id=etl_reddit_pipeline, task_id=reddit_extraction, execution_date=20250411T000000, start_date=20250414T170110, end_date=20250414T170112
[2025-04-14T17:01:12.877+0000] {local_task_job_runner.py:228} INFO - Task exited with return code 0
[2025-04-14T17:01:12.911+0000] {taskinstance.py:2778} INFO - 1 downstream tasks scheduled from follow-on schedule check
